2024-09-02 17:39:00,673 INFO    StreamThr :25335 [internal.py:wandb_internal():85] W&B internal server running at pid: 25335, started at: 2024-09-02 17:39:00.672339
2024-09-02 17:39:00,674 DEBUG   HandlerThread:25335 [handler.py:handle_request():158] handle_request: status
2024-09-02 17:39:00,679 INFO    WriterThread:25335 [datastore.py:open_for_write():87] open: /workspace/1L-Sparse-Autoencoder/wandb/run-20240902_173900-qef7vbva/run-qef7vbva.wandb
2024-09-02 17:39:00,679 DEBUG   SenderThread:25335 [sender.py:send():391] send: header
2024-09-02 17:39:00,684 DEBUG   SenderThread:25335 [sender.py:send():391] send: run
2024-09-02 17:39:00,781 ERROR   SenderThread:25335 [internal_api.py:execute():349] 404 response executing GraphQL.
2024-09-02 17:39:00,782 ERROR   SenderThread:25335 [internal_api.py:execute():350] {"errors":[{"message":"project not found","path":["upsertBucket"]}],"data":{"upsertBucket":null}}
2024-09-02 17:39:00,782 ERROR   SenderThread:25335 [sender.py:send_run():1021] It appears that you do not have permission to access the requested resource. Please reach out to the project owner to grant you access. If you have the correct permissions, verify that there are no issues with your networking setup.(Error 404: Not Found)
Traceback (most recent call last):
  File "/usr/local/lib/python3.10/dist-packages/wandb/sdk/lib/retry.py", line 131, in __call__
    result = self._call_fn(*args, **kwargs)
  File "/usr/local/lib/python3.10/dist-packages/wandb/sdk/internal/internal_api.py", line 345, in execute
    return self.client.execute(*args, **kwargs)  # type: ignore
  File "/usr/local/lib/python3.10/dist-packages/wandb/vendor/gql-0.2.0/wandb_gql/client.py", line 52, in execute
    result = self._get_result(document, *args, **kwargs)
  File "/usr/local/lib/python3.10/dist-packages/wandb/vendor/gql-0.2.0/wandb_gql/client.py", line 60, in _get_result
    return self.transport.execute(document, *args, **kwargs)
  File "/usr/local/lib/python3.10/dist-packages/wandb/sdk/lib/gql_request.py", line 59, in execute
    request.raise_for_status()
  File "/usr/local/lib/python3.10/dist-packages/requests/models.py", line 1024, in raise_for_status
    raise HTTPError(http_error_msg, response=self)
requests.exceptions.HTTPError: 404 Client Error: Not Found for url: https://api.wandb.ai/graphql

During handling of the above exception, another exception occurred:

Traceback (most recent call last):
  File "/usr/local/lib/python3.10/dist-packages/wandb/sdk/internal/sender.py", line 1019, in send_run
    server_run = self._init_run(run, config_value_dict)
  File "/usr/local/lib/python3.10/dist-packages/wandb/sdk/internal/sender.py", line 1091, in _init_run
    server_run, inserted, server_messages = self._api.upsert_run(
  File "/usr/local/lib/python3.10/dist-packages/wandb/apis/normalize.py", line 73, in wrapper
    raise err
  File "/usr/local/lib/python3.10/dist-packages/wandb/apis/normalize.py", line 41, in wrapper
    return func(*args, **kwargs)
  File "/usr/local/lib/python3.10/dist-packages/wandb/sdk/internal/internal_api.py", line 2224, in upsert_run
    response = self.gql(
  File "/usr/local/lib/python3.10/dist-packages/wandb/sdk/internal/internal_api.py", line 317, in gql
    ret = self._retry_gql(
  File "/usr/local/lib/python3.10/dist-packages/wandb/sdk/lib/retry.py", line 147, in __call__
    retry_timedelta_triggered = check_retry_fn(e)
  File "/usr/local/lib/python3.10/dist-packages/wandb/util.py", line 968, in check_retry_fn
    return fallback_retry_fn(e)
  File "/usr/local/lib/python3.10/dist-packages/wandb/util.py", line 910, in no_retry_auth
    raise CommError(
wandb.errors.CommError: It appears that you do not have permission to access the requested resource. Please reach out to the project owner to grant you access. If you have the correct permissions, verify that there are no issues with your networking setup.(Error 404: Not Found)
2024-09-02 17:39:01,037 DEBUG   HandlerThread:25335 [handler.py:handle_request():158] handle_request: shutdown
2024-09-02 17:39:01,038 INFO    HandlerThread:25335 [handler.py:finish():884] shutting down handler
2024-09-02 17:39:01,684 INFO    WriterThread:25335 [datastore.py:close():296] close: /workspace/1L-Sparse-Autoencoder/wandb/run-20240902_173900-qef7vbva/run-qef7vbva.wandb
2024-09-02 17:39:01,784 INFO    SenderThread:25335 [sender.py:finish():1631] shutting down sender
